<?xml version="1.0" encoding="UTF-8"?>
<!-- Generated by org.testng.reporters.JUnitReportReporter -->
<testsuite hostname="sebastian-thinkpad-t530" name="com.testprojects.facebook.tests.FacebookRatingTest" tests="4" failures="2" timestamp="10 Nov 2017 16:33:54 GMT" time="11.893" errors="2">
  <testcase name="facebookRatingCompare" time="5.920" classname="com.testprojects.facebook.tests.FacebookRatingTest">
    <failure type="java.lang.AssertionError" message="2 start should be more than 3 start expected [false] but found [true]">
      <![CDATA[java.lang.AssertionError: 2 start should be more than 3 start expected [false] but found [true]
	at org.testng.Assert.fail(Assert.java:94)
	at org.testng.Assert.failNotEquals(Assert.java:496)
	at org.testng.Assert.assertFalse(Assert.java:63)
	at test(FacebookAppTest.java:74)
	at sun.reflect.NativeMethodAccessorImpl.invoke0(Native Method)
	at sun.reflect.NativeMethodAccessorImpl.invoke(NativeMethodAccessorImpl.java:62)
	at sun.reflect.DelegatingMethodAccessorImpl.invoke(DelegatingMethodAccessorImpl.java:43)
	at java.lang.reflect.Method.invoke(Method.java:498)
	at org.testng.internal.MethodInvocationHelper.invokeMethod(MethodInvocationHelper.java:85)
	at org.testng.internal.Invoker.invokeMethod(Invoker.java:659)
	at org.testng.internal.Invoker.invokeTestMethod(Invoker.java:845)
	at org.testng.internal.Invoker.invokeTestMethods(Invoker.java:1153)
	at org.testng.internal.TestMethodWorker.invokeTestMethods(TestMethodWorker.java:125)
	at org.testng.internal.TestMethodWorker.run(TestMethodWorker.java:108)
	at org.testng.TestRunner.privateRun(TestRunner.java:771)
	at org.testng.TestRunner.run(TestRunner.java:621)
	at org.testng.SuiteRunner.runTest(SuiteRunner.java:357)
	at org.testng.SuiteRunner.runSequentially(SuiteRunner.java:352)
	at org.testng.SuiteRunner.privateRun(SuiteRunner.java:310)
	at org.testng.SuiteRunner.run(SuiteRunner.java:259)
	at org.testng.SuiteRunnerWorker.runSuite(SuiteRunnerWorker.java:52)
	at org.testng.SuiteRunnerWorker.run(SuiteRunnerWorker.java:86)
	at org.testng.TestNG.runSuitesSequentially(TestNG.java:1199)
	at org.testng.TestNG.runSuitesLocally(TestNG.java:1124)
	at org.testng.TestNG.run(TestNG.java:1032)
	at org.testng.IDEARemoteTestNG.run(IDEARemoteTestNG.java:72)
	at org.testng.RemoteTestNGStarter.main(RemoteTestNGStarter.java:123)
]]>
    </failure>
  </testcase> <!-- facebookRatingCompare -->
  <testcase name="facebookRatingCompare" time="5.973" classname="com.testprojects.facebook.tests.FacebookRatingTest">
    <failure type="java.lang.AssertionError" message="2 start should be more than 3 start expected [false] but found [true]">
      <![CDATA[java.lang.AssertionError: 2 start should be more than 3 start expected [false] but found [true]
	at org.testng.Assert.fail(Assert.java:94)
	at org.testng.Assert.failNotEquals(Assert.java:496)
	at org.testng.Assert.assertFalse(Assert.java:63)
	at test(FacebookAppTest.java:74)
	at sun.reflect.NativeMethodAccessorImpl.invoke0(Native Method)
	at sun.reflect.NativeMethodAccessorImpl.invoke(NativeMethodAccessorImpl.java:62)
	at sun.reflect.DelegatingMethodAccessorImpl.invoke(DelegatingMethodAccessorImpl.java:43)
	at java.lang.reflect.Method.invoke(Method.java:498)
	at org.testng.internal.MethodInvocationHelper.invokeMethod(MethodInvocationHelper.java:85)
	at org.testng.internal.Invoker.invokeMethod(Invoker.java:659)
	at org.testng.internal.Invoker.invokeTestMethod(Invoker.java:845)
	at org.testng.internal.Invoker.invokeTestMethods(Invoker.java:1153)
	at org.testng.internal.TestMethodWorker.invokeTestMethods(TestMethodWorker.java:125)
	at org.testng.internal.TestMethodWorker.run(TestMethodWorker.java:108)
	at org.testng.TestRunner.privateRun(TestRunner.java:771)
	at org.testng.TestRunner.run(TestRunner.java:621)
	at org.testng.SuiteRunner.runTest(SuiteRunner.java:357)
	at org.testng.SuiteRunner.runSequentially(SuiteRunner.java:352)
	at org.testng.SuiteRunner.privateRun(SuiteRunner.java:310)
	at org.testng.SuiteRunner.run(SuiteRunner.java:259)
	at org.testng.SuiteRunnerWorker.runSuite(SuiteRunnerWorker.java:52)
	at org.testng.SuiteRunnerWorker.run(SuiteRunnerWorker.java:86)
	at org.testng.TestNG.runSuitesSequentially(TestNG.java:1199)
	at org.testng.TestNG.runSuitesLocally(TestNG.java:1124)
	at org.testng.TestNG.run(TestNG.java:1032)
	at org.testng.IDEARemoteTestNG.run(IDEARemoteTestNG.java:72)
	at org.testng.RemoteTestNGStarter.main(RemoteTestNGStarter.java:123)
]]>
    </failure>
  </testcase> <!-- facebookRatingCompare -->
  <testcase name="aaa" time="0.000" classname="com.testprojects.facebook.tests.FacebookRatingTest">
    <error type="java.lang.Throwable" message="Method FacebookAppTest.aaa()[pri:0, instance:com.testprojects.facebook.tests.FacebookRatingTest@6833ce2c] depends on not successfully finished methods">
      <![CDATA[java.lang.Throwable: Method FacebookAppTest.aaa()[pri:0, instance:com.testprojects.facebook.tests.FacebookRatingTest@6833ce2c] depends on not successfully finished methods
	at org.testng.internal.Invoker.invokeTestMethods(Invoker.java:1063)
	at org.testng.internal.TestMethodWorker.invokeTestMethods(TestMethodWorker.java:125)
	at org.testng.internal.TestMethodWorker.run(TestMethodWorker.java:108)
	at org.testng.TestRunner.privateRun(TestRunner.java:771)
	at org.testng.TestRunner.run(TestRunner.java:621)
	at org.testng.SuiteRunner.runTest(SuiteRunner.java:357)
	at org.testng.SuiteRunner.runSequentially(SuiteRunner.java:352)
	at org.testng.SuiteRunner.privateRun(SuiteRunner.java:310)
	at org.testng.SuiteRunner.run(SuiteRunner.java:259)
	at org.testng.SuiteRunnerWorker.runSuite(SuiteRunnerWorker.java:52)
	at org.testng.SuiteRunnerWorker.run(SuiteRunnerWorker.java:86)
	at org.testng.TestNG.runSuitesSequentially(TestNG.java:1199)
	at org.testng.TestNG.runSuitesLocally(TestNG.java:1124)
	at org.testng.TestNG.run(TestNG.java:1032)
	at org.testng.IDEARemoteTestNG.run(IDEARemoteTestNG.java:72)
	at org.testng.RemoteTestNGStarter.main(RemoteTestNGStarter.java:123)
]]>
    </error>
  </testcase> <!-- aaa -->
  <testcase name="aaa" time="0.000" classname="com.testprojects.facebook.tests.FacebookRatingTest">
    <error type="java.lang.Throwable" message="Method FacebookAppTest.aaa()[pri:0, instance:com.testprojects.facebook.tests.FacebookRatingTest@3cb5cdba] depends on not successfully finished methods">
      <![CDATA[java.lang.Throwable: Method FacebookAppTest.aaa()[pri:0, instance:com.testprojects.facebook.tests.FacebookRatingTest@3cb5cdba] depends on not successfully finished methods
	at org.testng.internal.Invoker.invokeTestMethods(Invoker.java:1063)
	at org.testng.internal.TestMethodWorker.invokeTestMethods(TestMethodWorker.java:125)
	at org.testng.internal.TestMethodWorker.run(TestMethodWorker.java:108)
	at org.testng.TestRunner.privateRun(TestRunner.java:771)
	at org.testng.TestRunner.run(TestRunner.java:621)
	at org.testng.SuiteRunner.runTest(SuiteRunner.java:357)
	at org.testng.SuiteRunner.runSequentially(SuiteRunner.java:352)
	at org.testng.SuiteRunner.privateRun(SuiteRunner.java:310)
	at org.testng.SuiteRunner.run(SuiteRunner.java:259)
	at org.testng.SuiteRunnerWorker.runSuite(SuiteRunnerWorker.java:52)
	at org.testng.SuiteRunnerWorker.run(SuiteRunnerWorker.java:86)
	at org.testng.TestNG.runSuitesSequentially(TestNG.java:1199)
	at org.testng.TestNG.runSuitesLocally(TestNG.java:1124)
	at org.testng.TestNG.run(TestNG.java:1032)
	at org.testng.IDEARemoteTestNG.run(IDEARemoteTestNG.java:72)
	at org.testng.RemoteTestNGStarter.main(RemoteTestNGStarter.java:123)
]]>
    </error>
  </testcase> <!-- aaa -->
</testsuite> <!-- com.testprojects.facebook.tests.FacebookRatingTest -->
